Workbook

Sheet CONTROL
A1: EL BOTÁNICO - PANEL DE CONTROL
D2: Indicador | E2: Valor
A3: Ventas Totales | B3: =SUM(Ventas!H:H) -> 8702400 | D3: Ventas Totales | E3: =B3 -> 8702400
A4: Costos Totales | B4: =SUM(Costos!D:D) -> 120984.34 | D4: Costos Totales | E4: =B4 -> 120984.34
A5: Ganancia Neta | B5: =B3-B4 -> 8581415.7 | D5: Ganancia Neta | E5: =B5 -> 8581415.7
A6: Valor de Stock | B6: =SUM(#REF!) -> #REF! | D6: Valor de Stock | E6: =B6 -> #REF!
A11: EGRESOS
A12: BALANZA | B12: 10900
A13: LIBRERÍA | B13: 18000
A14: BOLSAS DE ARPILLERA | B14: 20000
A15: MARTITA HIJO | B15: 571200
A16: POLISOL | B16: 25000
A17: PARAGUAYA | B17: 175000
A18: MARTITA HIJO | B18: 150000 | D18: *
A19: MARTITA HIJO | B19: 187000
A20: PARAGUAYA | B20: 193000
A21: LUIS ANDRADE | B21: 223800
A22: COMPRAS MACETS JUJEÑO | B22: 152000
A23: NORTE GRAFICA | B23: 25600
A24: MEDIA SOMBRA | B24: 112000
A25: FLETE POSTES | B25: 60000
A26: VENTILADOR | B26: 45000
A27: VENTI | B27: 30000
A28: MANTILLO | B28: 25000
A29: CLAUDIIO | B29: 80000
A30: VEGUITA | B30: 80000
... A45: BRASILERO | B45: 253000
A46: SECHEEP | B46: =11656+14101.46 -> 25757.46
A47: MAURO | B47: 15000
A48: PICA PICA | B48: 30000
A49: CLAUDIO | B49: 60000
A50: TIERRA NEGRA | B50: 170000
A51: BOMBA RIEGO | B51: 118000
A52: PIUNTURA | B52: 16000
A53: SAMEEP | B53: 39504.26
A54: ARENA | B54: 97000
A55: ELECTRICIDAD | B55: 81830
A56: cemento | B56: 32000
A57: GABRIEL MARTITA HIJO | B57: 300000
A58: transplantes raul luquitas | B58: 120000
...

Sheet COMPRAS
A1: ESPECIE | B1: Maceta (LTS.) | C1: Cantidad | D1: Costo Unit.
A2: HERBACEAS PERENNES/CADUCAS
A3: AGAVE AMERICANO
A4: AGAVE AMERICANO VARIEGADO
A5: AGAVE ANGUSTIFOLIA MAGUEY
A6: AGAVE ATENUATA
A7: AGAVE DESMETTIANA
A8: AGAVE DESMETTIANA VARIEGADO
A9: AGLONEMA FREEDMAN | B9: 3 | C9: 3 | D9: 12828
A10: AGLONEMA PATTAYA | B10: 2/3L | C10: 10 | D10: 12828
A11: AGLONEMA PINK | B11: 3 | C11: 10 | D11: 4000
A12: ALEGRIA DEL HOGAR | C12: =14+45+15 -> 74 | D12: 700
A13: ALISO DE MAR (LOBULARIA MARITIMA) | B13: 1 | C13: =2+10+8+20+20 -> 60 | D13: 1500
A14: ALPINIA | B14: 3 | C14: 24 | D14: 3000
A15: ALTERNANTHERA BRASILIANA | F15: 6
A16: ALTERNANTHERA FICOIDEA RED
A17: ALTERNANTHERA FICOIDEA VERDE
A18: ALOCACIA (OREJA DE ELEFANTE) CHICA | C18: =4+5 -> 9 | D18: =14000/4 -> 3500
A19: ALOCACIA (OREJA DE ELEFANTE) MEDIANA | C19: 7 | D19: 5000
A20: ALOCACIA (OREJA DE ELEFANTE) GRANDE | B20: M15 | C20: 2 | D20: =32000/2 -> 16000
A21: ANTHURIUM | B21: 3/5L | C21: 14 | D21: 0
A22: ANTHURIUM ROJO | B22: 0.9 | C22: 6 | D22: 10000
A23: ASTA DE CIERVO | C23: 3 | D23: 0
A24: ASCLEPIA | C24: 9 | D24: =22500/9 -> 2500
A25: AZUCENA DE MEXICO | B25: 2/3L | C25: 22 | D25: 0
A26: BEGONIA ALA DE ANGEL | B26: 5 | C26: 4 | D26: 0
A27: BEGONIA DRAGON | B27: 3 | C27: 10 | D27: 3000
A28: BEGONIA HIRTELLA | B28: 3 | C28: 5 | D28: 0
A29: BEGONIA BOOMER | B29: COLGANTE | C29: 3 | D29: 4500
A30: BEGONIA RED | C30: 12 | D30: 700
A31: BEGONIA REY (PLATEADA) | B31: COLGANTE | C31: 2 | D31: 5500
A32: BROMELIA (LAGRIMA DE REINA) | B32: 3 | C32: 4 | D32: 0
A33: BROMELIA FOSFORITO | B33: 1/2L | C33: 4 | D33: 0
A34: CALA BLANCA | C34: =5+4 -> 9 | D34: 6500
A35: CALATHEA MACOYANA | B35: 1.5 | C35: 5 | D35: 10000
A36: CALATHEA MACOYANA CHICA | B36: 0.5 | C36: 5 | D36: 3100
A37: CALATHEA MIL RAYAS | B37: 3 | C37: 5 | D37: 9000
A38: CALATHEA ZEBRINA | B38: 5 | C38: 5 | D38: 18000
A39: CALISTEMO | C39: 5 | D39: 3000
A40: CLAVELINA | C40: 60 | D40: 770
...

Sheet INVENTARIO
A1: ESPECIE | B1: Maceta (LTS.) | C1: Cantidad | D1: Costo Unit. | E1: Precio Venta | F1: Margen Neto | G1: Existencias
A2: HERBACEAS PERENNES/CADUCAS
A3: AGAVE AMERICANO | B3: =+COMPRAS!B3:B108 -> 0 | C3: =+InventarioTbl3[[#This Row],[Cantidad]] -> 0 | D3: =+InventarioTbl3[[#This Row],[Costo Unit.]] -> 0 | F3: =+E3-InventarioTbl34[[#This Row],[Costo Unit.]] -> 0 | G3: =C3-SUMIF(Ventas!D:D,"AGAVE AMERICANO",Ventas!F:F) -> 0
A4: AGAVE AMERICANO VARIEGADO | B4: =+COMPRAS!B4:B115 -> 0 | C4: =+InventarioTbl3[[#This Row],[Cantidad]] -> 0 | D4: =+InventarioTbl3[[#This Row],[Costo Unit.]] -> 0 | F4: =+E4-InventarioTbl34[[#This Row],[Costo Unit.]] -> 0 | G4: =C4-SUMIF(Ventas!D:D,"AGAVE AMERICANO VARIEGADO",Ventas!F:F) -> 0
A5: AGAVE ANGUSTIFOLIA MAGUEY | B5: =+COMPRAS!B5:B116 -> 0 | C5: =+InventarioTbl3[[#This Row],[Cantidad]] -> 0 | D5: =+InventarioTbl3[[#This Row],[Costo Unit.]] -> 0 | F5: =+E5-InventarioTbl34[[#This Row],[Costo Unit.]] -> 0 | G5: =C5-SUMIF(Ventas!D:D,"AGAVE ANGUSTIFOLIA MAGUEY",Ventas!F:F) -> 0
A6: AGAVE ATENUATA | B6: =+COMPRAS!B6:B117 -> 0 | C6: =+InventarioTbl3[[#This Row],[Cantidad]] -> 0 | D6: =+InventarioTbl3[[#This Row],[Costo Unit.]] -> 0 | F6: =+E6-InventarioTbl34[[#This Row],[Costo Unit.]] -> 0 | G6: =C6-SUMIF(Ventas!D:D,"AGAVE ATENUATA",Ventas!F:F) -> 0
A7: AGAVE DESMETTIANA | B7: =+COMPRAS!B7:B118 -> 0 | C7: =+InventarioTbl3[[#This Row],[Cantidad]] -> 0 | D7: =+InventarioTbl3[[#This Row],[Costo Unit.]] -> 0 | F7: =+E7-InventarioTbl34[[#This Row],[Costo Unit.]] -> 0 | G7: =C7-SUMIF(Ventas!D:D,"AGAVE DESMETTIANA VARIEGADO",Ventas!F:F) -> 0
A8: AGAVE DESMETTIANA VARIEGADO | B8: =+COMPRAS!B8:B119 -> 0 | C8: =+InventarioTbl3[[#This Row],[Cantidad]] -> 0 | D8: =+InventarioTbl3[[#This Row],[Costo Unit.]] -> 0 | F8: =+E8-InventarioTbl34[[#This Row],[Costo Unit.]] -> 0 | G8: =C8-SUMIF(Ventas!D:D,"AGAVE DESMETTIANA VARIEGADO",Ventas!F:F) -> 0
A9: AGLONEMA FREEDMAN | B9: =+COMPRAS!B9:B120 -> 3 | C9: =+InventarioTbl3[[#This Row],[Cantidad]] -> 3 | D9: =+InventarioTbl3[[#This Row],[Costo Unit.]] -> 12828 | E9: 20000 | F9: =+E9-InventarioTbl34[[#This Row],[Costo Unit.]] -> 7172 | G9: =C9-SUMIF(Ventas!D:D,"AGLONEMA FREEDMAN",Ventas!F:F) -> 3
A10: AGLONEMA PATTAYA | B10: =+COMPRAS!B10:B121 -> 2/3L | C10: =+InventarioTbl3[[#This Row],[Cantidad]] -> 10 | D10: =+InventarioTbl3[[#This Row],[Costo Unit.]] -> 12828 | E10: 20000 | F10: =+E10-InventarioTbl34[[#This Row],[Costo Unit.]] -> 7172 | G10: =C10-SUMIF(Ventas!D:D,"AGLONEMA PATTAYA",Ventas!F:F) -> 10
A11: AGLONEMA PINK | B11: =+COMPRAS!B11:B122 -> 3 | C11: =+InventarioTbl3[[#This Row],[Cantidad]] -> 10 | D11: =+InventarioTbl3[[#This Row],[Costo Unit.]] -> 4000 | E11: 9000 | F11: =+E11-InventarioTbl34[[#This Row],[Costo Unit.]] -> 5000 | G11: =C11-SUMIF(Ventas!D:D,"AGLONEMA PINK",Ventas!F:F) -> 6
A12: =+InventarioTbl3[[#This Row],[ESPECIE]] -> ALEGRIA DEL HOGAR | C12: =+InventarioTbl3[[#This Row],[Cantidad]] -> 74 | D12: =+InventarioTbl3[[#This Row],[Costo Unit.]] -> 700 | E12: 3000 | F12: =+E12-InventarioTbl34[[#This Row],[Costo Unit.]] -> 2300 | G12: =C12-SUMIF(Ventas!D:D,"ALEGRIA",Ventas!F:F) -> 73
A13: ALISO DE MAR (LOBULARIA MARITIMA) | B13: =+COMPRAS!B13:B125 -> 1 | C13: =+InventarioTbl3[[#This Row],[Cantidad]] -> 60 | D13: =+InventarioTbl3[[#This Row],[Costo Unit.]] -> 1500 | E13: 3500 | F13: =+E13-InventarioTbl34[[#This Row],[Costo Unit.]] -> 2000 | G13: =C13-SUMIF(Ventas!D:D,"ALISO DE MAR",Ventas!F:F) -> 29
A14: ALPINIA | B14: =+COMPRAS!B14:B126 -> 3 | C14: =+InventarioTbl3[[#This Row],[Cantidad]] -> 24 | D14: =+InventarioTbl3[[#This Row],[Costo Unit.]] -> 3000 | E14: 12000 | F14: =+E14-InventarioTbl34[[#This Row],[Costo Unit.]] -> 9000 | G14: =C14-SUMIF(Ventas!D:D,"ALPINIA",Ventas!F:F) -> 23
A15: ALTERNANTHERA BRASILIANA | B15: =+COMPRAS!B15:B126 -> 0 | C15: =+InventarioTbl3[[#This Row],[Cantidad]] -> 0 | D15: =+InventarioTbl3[[#This Row],[Costo Unit.]] -> 0 | F15: =+E15-InventarioTbl34[[#This Row],[Costo Unit.]] -> 0 | G15: =C15-SUMIF(Ventas!D:D,"ALTERNANTHERA BRASILIANA",Ventas!F:F) -> 0
A16: ALTERNANTHERA FICOIDEA RED | B16: =+COMPRAS!B16:B127 -> 0 | C16: =+InventarioTbl3[[#This Row],[Cantidad]] -> 0 | D16: =+InventarioTbl3[[#This Row],[Costo Unit.]] -> 0 | F16: =+E16-InventarioTbl34[[#This Row],[Costo Unit.]] -> 0 | G16: =C16-SUMIF(Ventas!D:D,"ALTERNANTHERA FICOIDEA RED",Ventas!F:F) -> 0
A17: ALTERNANTHERA FICOIDEA VERDE | B17: =+COMPRAS!B17:B128 -> 0 | C17: =+InventarioTbl3[[#This Row],[Cantidad]] -> 0 | D17: =+InventarioTbl3[[#This Row],[Costo Unit.]] -> 0 | F17: =+E17-InventarioTbl34[[#This Row],[Costo Unit.]] -> 0 | G17: =C17-SUMIF(Ventas!D:D,"ALTERNANTHERA FICOIDEA VERDE",Ventas!F:F) -> 0
A18: =+InventarioTbl3[[#This Row],[ESPECIE]] -> ALOCACIA (OREJA DE ELEFANTE) CHICA | B18: =+COMPRAS!B18:B129 -> 0 | C18: =+InventarioTbl3[[#This Row],[Cantidad]] -> 9 | D18: =+InventarioTbl3[[#This Row],[Costo Unit.]] -> 3500 | E18: 10000 | F18: =+E18-InventarioTbl34[[#This Row],[Costo Unit.]] -> 6500 | G18: =C18-SUMIF(Ventas!D:D,"ALOCACIA CHICA",Ventas!F:F) -> 9
A19: =+InventarioTbl3[[#This Row],[ESPECIE]] -> ALOCACIA (OREJA DE ELEFANTE) MEDIANA | B19: =+COMPRAS!B19:B130 -> 0 | C19: =+InventarioTbl3[[#This Row],[Cantidad]] -> 7 | D19: =+InventarioTbl3[[#This Row],[Costo Unit.]] -> 5000 | E19: 15000 | F19: =+E19-InventarioTbl34[[#This Row],[Costo Unit.]] -> 10000 | G19: =C19-SUMIF(Ventas!D:D,"ALOCACIA MEDIANA",Ventas!F:F) -> 4
A20: =+InventarioTbl3[[#This Row],[ESPECIE]] -> ALOCACIA (OREJA DE ELEFANTE) GRANDE | B20: =+COMPRAS!B20:B130 -> M15 | C20: =+InventarioTbl3[[#This Row],[Cantidad]] -> 2 | D20: =+InventarioTbl3[[#This Row],[Costo Unit.]] -> 16000 | E20: 40000 | F20: =+E20-InventarioTbl34[[#This Row],[Costo Unit.]] -> 24000 | G20: =C20-SUMIF(Ventas!D:D,"ALOCACIA GRANDE",Ventas!F:F) -> 2
A21: ANTHURIUM | B21: =+COMPRAS!B21:B129 -> 3/5L | C21: =+InventarioTbl3[[#This Row],[Cantidad]] -> 14 | D21: =+InventarioTbl3[[#This Row],[Costo Unit.]] -> 0 | E21: 14000 | F21: =+E21-InventarioTbl34[[#This Row],[Costo Unit.]] -> 14000 | G21: =C21-SUMIF(Ventas!D:D,"ANTHURIUM",Ventas!F:F) -> 12
A22: ANTHURIUM ROJO | B22: =+COMPRAS!B22:B130 -> 0.9 | C22: =+InventarioTbl3[[#This Row],[Cantidad]] -> 6 | D22: =+InventarioTbl3[[#This Row],[Costo Unit.]] -> 10000 | E22: 13000 | F22: =+E22-InventarioTbl34[[#This Row],[Costo Unit.]] -> 3000 | G22: =C22-SUMIF(Ventas!D:D,"ANTHURIUM ROJO",Ventas!F:F) -> 6
A23: =+InventarioTbl3[[#This Row],[ESPECIE]] -> ASTA DE CIERVO | C23: =+InventarioTbl3[[#This Row],[Cantidad]] -> 3 | D23: =+InventarioTbl3[[#This Row],[Costo Unit.]] -> 0 | E23: 40000/60000 | G23: =C23-SUMIF(Ventas!D:D,"ASTA DE CIERVO",Ventas!F:F) -> 2
A24: =+COMPRAS!A24 -> ASCLEPIA | C24: =+InventarioTbl3[[#This Row],[Cantidad]] -> 9 | D24: =+InventarioTbl3[[#This Row],[Costo Unit.]] -> 2500 | E24: 7500 | F24: =+E24-InventarioTbl34[[#This Row],[Costo Unit.]] -> 5000 | G24: =C24-SUMIF(Ventas!D:D,"ASCLEPIA",Ventas!F:F) -> 6
A25: AZUCENA DE MEXICO | B25: =+COMPRAS!B25:B132 -> 2/3L | C25: =+InventarioTbl3[[#This Row],[Cantidad]] -> 22 | D25: =+InventarioTbl3[[#This Row],[Costo Unit.]] -> 0 | E25: 10000 | F25: =+E25-InventarioTbl34[[#This Row],[Costo Unit.]] -> 10000 | G25: =C25-SUMIF(Ventas!D:D,"AZUCENA DE MEXICO",Ventas!F:F) -> 21
A26: BEGONIA ALA DE ANGEL | B26: =+COMPRAS!B26:B133 -> 5 | C26: =+InventarioTbl3[[#This Row],[Cantidad]] -> 4 | D26: =+InventarioTbl3[[#This Row],[Costo Unit.]] -> 0 | E26: 10000 | F26: =+E26-InventarioTbl34[[#This Row],[Costo Unit.]] -> 10000 | G26: =C26-SUMIF(Ventas!D:D,"BEGONIA ALA DE ANGEL",Ventas!F:F) -> 4
A27: BEGONIA DRAGON | B27: =+COMPRAS!B27:B134 -> 3 | C27: =+InventarioTbl3[[#This Row],[Cantidad]] -> 10 | D27: =+InventarioTbl3[[#This Row],[Costo Unit.]] -> 3000 | E27: 10000 | F27: =+E27-InventarioTbl34[[#This Row],[Costo Unit.]] -> 7000 | G27: =C27-SUMIF(Ventas!D:D,"BEGONIA DRAGON",Ventas!F:F) -> 5
A28: BEGONIA HIRTELLA | B28: =+COMPRAS!B28:B135 -> 3 | C28: =+InventarioTbl3[[#This Row],[Cantidad]] -> 5 | D28: =+InventarioTbl3[[#This Row],[Costo Unit.]] -> 0 | E28: 10000 | F28: =+E28-InventarioTbl34[[#This Row],[Costo Unit.]] -> 10000 | G28: =C28-SUMIF(Ventas!D:D,"BEGONIA HIRTELLA",Ventas!F:F) -> 5
A29: BEGONIA BOOMER | B29: =+COMPRAS!B29:B136 -> COLGANTE | C29: =+InventarioTbl3[[#This Row],[Cantidad]] -> 3 | D29: =+InventarioTbl3[[#This Row],[Costo Unit.]] -> 4500 | E29: 10000 | F29: =+E29-InventarioTbl34[[#This Row],[Costo Unit.]] -> 5500 | G29: =C29-SUMIF(Ventas!D:D,"BEGONIA BOOMER",Ventas!F:F) -> 0
A30: =+InventarioTbl3[[#This Row],[ESPECIE]] -> BEGONIA RED | B30: =+COMPRAS!B30:B137 -> 0 | C30: =+InventarioTbl3[[#This Row],[Cantidad]] -> 12 | D30: =+InventarioTbl3[[#This Row],[Costo Unit.]] -> 700 | E30: 2500 | F30: =+E30-InventarioTbl34[[#This Row],[Costo Unit.]] -> 1800 | G30: =C30-SUMIF(Ventas!D:D,"BEGONIA RED",Ventas!F:F) -> 11
A31: =+InventarioTbl3[[#This Row],[ESPECIE]] -> BEGONIA REY (PLATEADA) | B31: =+COMPRAS!B31:B138 -> COLGANTE | C31: =+InventarioTbl3[[#This Row],[Cantidad]] -> 2 | D31: =+InventarioTbl3[[#This Row],[Costo Unit.]] -> 5500 | E31: 10000 | F31: =+E31-InventarioTbl34[[#This Row],[Costo Unit.]] -> 4500 | G31: =C31-SUMIF(Ventas!D:D,"BEGONIA REY",Ventas!F:F) -> 1
A32: BROMELIA (LAGRIMA DE REINA) | B32: =+COMPRAS!B32:B138 -> 3 | C32: =+InventarioTbl3[[#This Row],[Cantidad]] -> 4 | D32: =+InventarioTbl3[[#This Row],[Costo Unit.]] -> 0 | E32: 12000 | F32: =+E32-InventarioTbl34[[#This Row],[Costo Unit.]] -> 12000 | G32: =C32-SUMIF(Ventas!D:D,"BROMELIA",Ventas!F:F) -> 4
A33: BROMELIA FOSFORITO | B33: =+COMPRAS!B33:B140 -> 1/2L | C33: =+InventarioTbl3[[#This Row],[Cantidad]] -> 4 | D33: =+InventarioTbl3[[#This Row],[Costo Unit.]] -> 0 | E33: 15000 | F33: =+E33-InventarioTbl34[[#This Row],[Costo Unit.]] -> 15000 | G33: =C33-SUMIF(Ventas!D:D,"BROMELIA FOSFORITO",Ventas!F:F) -> 4
A34: =+InventarioTbl3[[#This Row],[ESPECIE]] -> CALA BLANCA | B34: =+COMPRAS!B34:B142 -> 0 | C34: =+InventarioTbl3[[#This Row],[Cantidad]] -> 9 | D34: =+InventarioTbl3[[#This Row],[Costo Unit.]] -> 6500 | E34: 12000 | F34: =+E34-InventarioTbl34[[#This Row],[Costo Unit.]] -> 5500 | G34: =C34-SUMIF(Ventas!D:D,"CALA BLANCA",Ventas!F:F) -> 5
A35: CALATHEA MACOYANA | B35: =+COMPRAS!B35:B142 -> 1.5 | C35: =+InventarioTbl3[[#This Row],[Cantidad]] -> 5 | D35: =+InventarioTbl3[[#This Row],[Costo Unit.]] -> 10000 | E35: 20000 | F35: =+E35-InventarioTbl34[[#This Row],[Costo Unit.]] -> 10000 | G35: =C35-SUMIF(Ventas!D:D,"CALATHEA MACOYANA",Ventas!F:F) -> 5
A36: =+InventarioTbl3[[#This Row],[ESPECIE]] -> CALATHEA MACOYANA CHICA | B36: =+COMPRAS!B36:B143 -> 0.5 | C36: =+InventarioTbl3[[#This Row],[Cantidad]] -> 5 | D36: =+InventarioTbl3[[#This Row],[Costo Unit.]] -> 3100 | E36: 10000 | F36: =+E36-InventarioTbl34[[#This Row],[Costo Unit.]] -> 6900 | G36: =C36-SUMIF(Ventas!D:D,"CALATHEA MACOYANA CHICA",Ventas!F:F) -> 3
A37: CALATHEA MIL RAYAS | B37: =+COMPRAS!B37:B143 -> 3 | C37: =+InventarioTbl3[[#This Row],[Cantidad]] -> 5 | D37: =+InventarioTbl3[[#This Row],[Costo Unit.]] -> 9000 | E37: 14000 | F37: =+E37-InventarioTbl34[[#This Row],[Costo Unit.]] -> 5000 | G37: =C37-SUMIF(Ventas!D:D,"CALATHEA MIL RAYAS",Ventas!F:F) -> 3
A38: CALATHEA ZEBRINA | B38: =+COMPRAS!B38:B144 -> 5 | C38: =+InventarioTbl3[[#This Row],[Cantidad]] -> 5 | D38: =+InventarioTbl3[[#This Row],[Costo Unit.]] -> 18000 | E38: 32000 | F38: =+E38-InventarioTbl34[[#This Row],[Costo Unit.]] -> 14000 | G38: =C38-SUMIF(Ventas!D:D,"CALATHEA ZEBRINA",Ventas!F:F) -> 0
A39: =+InventarioTbl3[[#This Row],[ESPECIE]] -> CALISTEMO | C39: =+InventarioTbl3[[#This Row],[Cantidad]] -> 5 | D39: =+InventarioTbl3[[#This Row],[Costo Unit.]] -> 3000 | E39: 10000 | F39: =+E39-InventarioTbl34[[#This Row],[Costo Unit.]] -> 7000 | G39: =C39-SUMIF(Ventas!D:D,"CALISTEMO",Ventas!F:F) -> 5
A40: =+InventarioTbl3[[#This Row],[ESPECIE]] -> CLAVELINA | C40: =+InventarioTbl3[[#This Row],[Cantidad]] -> 60 | D40: =+InventarioTbl3[[#This Row],[Costo Unit.]] -> 770 | E40: 3000 | F40: =+E40-InventarioTbl34[[#This Row],[Costo Unit.]] -> 2230 | G40: =C40-SUMIF(Ventas!D:D,"CLAVELINA",Ventas!F:F) -> 60
...

Sheet macetas
A1: TIPO DE MACETA | B1: Cantidad | C1: Costo Unit. | D1: Precio Venta | E1: Margen Neto | F1: NETO TOTAL | G1: Existencias
A2: GOTAS | F2: =SUM(E4:E58) -> 733819.9
A3: GOTA MINI | B3: =1+6 -> 7 | C3: 4500 | D3: 10000 | E3: =+D3-C3 -> 5500 | G3: =B3-SUMIF(Ventas!D:D,"GOTA Nº20",Ventas!F:F) -> 7
A4: GOTA Nº25 | B4: 1 | C4: 7500 | D4: 15000 | E4: =+D4-C4 -> 7500 | G4: =B4-SUMIF(Ventas!D:D,"GOTA Nº25",Ventas!F:F) -> 0
A5: GOTA Nº30 | B5: 4 | C5: 8500 | D5: 20000 | E5: =+D5-C5 -> 11500 | G5: =B5-SUMIF(Ventas!D:D,"GOTA Nº30",Ventas!F:F) -> 0
A6: GOTA Nº35 | B6: 2 | C6: 15000 | D6: 30000 | E6: =+D6-C6 -> 15000 | G6: =B6-SUMIF(Ventas!D:D,"GOTA Nº35",Ventas!F:F) -> 2
A7: GOTA Nº40 | B7: =2+2+2 -> 6 | C7: 14000 | D7: 40000 | E7: =+D7-C7 -> 26000 | G7: =B7-SUMIF(Ventas!D:D,"GOTA Nº40",Ventas!F:F) -> 5
A8: GOTA Nº50 | B8: =1+2 -> 3 | C8: 18000 | D8: 50000 | E8: =+D8-C8 -> 32000 | G8: =B8-SUMIF(Ventas!D:D,"GOTA Nº50",Ventas!F:F) -> 0
A9: GOTA LARGA | B9: 4 | C9: 15000 | D9: 30000 | E9: =+D9-C9 -> 15000 | G9: =B9-SUMIF(Ventas!D:D,"GOTA LARGA",Ventas!F:F) -> 3
A10: GOTA Nº50 ANCHA | B10: 2 | C10: 22000 | D10: 55000 | E10: =+D10-C10 -> 33000 | G10: =B10-SUMIF(Ventas!D:D,"GOTA Nº50 ANCHA",Ventas!F:F) -> 1
A11: GOTA Nº65 ANCHA | B11: 2 | C11: 25000 | D11: 60000 | E11: =+D11-C11 -> 35000 | G11: =B11-SUMIF(Ventas!D:D,"GOTA Nº65 ANCHA",Ventas!F:F) -> 1
A12: GOTA Nº67 | B12: 1 | C12: 22000 | D12: 60000 | E12: =+D12-C12 -> 38000 | G12: =B12-SUMIF(Ventas!D:D,"GOTA Nº67",Ventas!F:F) -> 1
A13: TINAJA Nº 65 | B13: 1 | C13: 22000 | D13: 55000 | E13: =+D13-C13 -> 33000 | G13: =B13-SUMIF(Ventas!D:D,"TIJANA Nº65",Ventas!F:F) -> 1
A14: ESQUINEROS | B14: 4 | C14: 15500 | D14: 25000 | E14: =+D14-C14 -> 9500 | G14: =B14-SUMIF(Ventas!D:D,"ESQUINEROS",Ventas!F:F) -> 4
A15: CUBOS
A16: CUBO 40X40 | B16: 1 | C16: 15000 | D16: 40000 | E16: =+D16-C16 -> 25000 | G16: =B16-SUMIF(Ventas!D:D,"CUBO 40X40",Ventas!F:F) -> 1
A17: CUBO 35X35 | B17: 2 | C17: 11000 | D17: 30000 | E17: =+D17-C17 -> 19000 | G17: =B17-SUMIF(Ventas!D:D,"CUBO 35X35",Ventas!F:F) -> 2
A18: CUBO 25X25 | B18: 2 | C18: 6000 | D18: 15000 | E18: =+D18-C18 -> 9000 | G18: =B18-SUMIF(Ventas!D:D,"CUBO 25X25",Ventas!F:F) -> 1
A19: CUBO 15X15 | B19: =2+4 -> 6 | C19: 4000 | D19: 10000 | E19: =+D19-C19 -> 6000 | G19: =B19-SUMIF(Ventas!D:D,"CUBO 15X15",Ventas!F:F) -> 5
A20: CONOS
A21: CONO N40 | B21: 2 | C21: 10000 | D21: 30000 | E21: =+D21-C21 -> 20000 | G21: =B21-SUMIF(Ventas!D:D,"CONO N40",Ventas!F:F) -> 2
A22: CONO N55 | B22: 2 | C22: 15000 | D22: 40000 | E22: =+D22-C22 -> 25000 | G22: =B22-SUMIF(Ventas!D:D,"CONO N55",Ventas!F:F) -> 2
A23: CONO N70 | B23: 2 | C23: 18000 | D23: 50000 | E23: =+D23-C23 -> 32000 | G23: =B23-SUMIF(Ventas!D:D,"CONO N70",Ventas!F:F) -> 2
A24: PIRAMIDAL
A25: PIRAMIDAL 80X35 | B25: 1 | C25: 19000 | D25: 60000 | E25: =+D25-C25 -> 41000 | G25: =B25-SUMIF(Ventas!D:D,"PIRAMIDAL 80X35",Ventas!F:F) -> 1
A26: PIRAMIDAL 60X50 | B26: 1 | C26: 20000 | D26: 55000 | E26: =+D26-C26 -> 35000 | G26: =B26-SUMIF(Ventas!D:D,"PIRAMIDAL 60X50",Ventas!F:F) -> 1
A27: PIRAMIDAL 40X30 | B27: 5 | C27: 8000 | D27: 25000 | E27: =+D27-C27 -> 17000 | G27: =B27-SUMIF(Ventas!D:D,"PIRAMIDAL 40X30",Ventas!F:F) -> 1
A28: PIRAMIDAL 30X25 | B28: 2 | C28: 6000 | D28: 20000 | E28: =+D28-C28 -> 14000 | G28: =B28-SUMIF(Ventas!D:D,"PIRAMIDAL 30X25",Ventas!F:F) -> 2
A29: PIRAMIDAL 20X20 | B29: 2 | C29: 4000 | D29: 15000 | E29: =+D29-C29 -> 11000 | G29: =B29-SUMIF(Ventas!D:D,"PIRAMIDAL 20X20",Ventas!F:F) -> 2
A30: PIRAMIDAL 70X35 | B30: 2 | C30: 17000 | D30: 35000 | E30: =+D30-C30 -> 18000 | G30: =B30-SUMIF(Ventas!D:D,"PIRAMIDAL 70X35",Ventas!F:F) -> 2
A31: PRISMA
A32: PRISMA 60X20 | B32: 2 | C32: 9000 | D32: 30000 | E32: =+D32-C32 -> 21000 | G32: =B32-SUMIF(Ventas!D:D,"PRISMA 60X20",Ventas!F:F) -> 2
A33: PRISMA 50X20 | B33: 2 | C33: 8000 | D33: 25000 | E33: =+D33-C33 -> 17000 | G33: =B33-SUMIF(Ventas!D:D,"PRISMA 50X20",Ventas!F:F) -> 2
A34: PRISMA 40X20 | B34: =2+2 -> 4 | C34: 8500 | D34: 20000 | E34: =+D34-C34 -> 11500 | G34: =B34-SUMIF(Ventas!D:D,"PRISMA 40X20",Ventas!F:F) -> 4
A35: PRISMA 30X20 | B35: 2 | C35: 6000 | D35: 15000 | E35: =+D35-C35 -> 9000 | G35: =B35-SUMIF(Ventas!D:D,"PRISMA 30X20",Ventas!F:F) -> 1
A36: JARDINERAS
A37: JARDINERA 1X20X20 | B37: 2 | C37: 12000 | D37: 25000 | E37: =+D37-C37 -> 13000 | G37: =B37-SUMIF(Ventas!D:D,"JARDINERA 1X20X20",Ventas!F:F) -> 2
A38: JARDINERA 50X20X20 | B38: 1 | C38: 7000 | D38: 15000 | E38: =+D38-C38 -> 8000 | G38: =B38-SUMIF(Ventas!D:D,"JARDINERA 50X20X20",Ventas!F:F) -> -1
A39: JARDINERA 80X30X30 | B39: =1+2 -> 3 | C39: 14000 | D39: 30000 | E39: =+D39-C39 -> 16000 | G39: =B39-SUMIF(Ventas!D:D,"JARDINERA 80X30X30",Ventas!F:F) -> 3
A40: JARDINERA 1X22X40 | B40: 1 | C40: 19500 | D40: 50000 | E40: =+D40-C40 -> 30500 | G40: =B40-SUMIF(Ventas!D:D,"JARDINERA 1X22X40",Ventas!F:F) -> 1
...

Sheet Ventas
A1: Fecha | B1: Nombre Cliente | C1: Tel. | D1: Especie | E1: Maceta | F1: Cantidad | G1: Precio Unit. | H1: Total | I1: TOTAL JORNADA | J1: TOTAL PONDERADO
A2: 46243 | B2: DUEÑA DE CUBO | D2: CALATEA MIL RAYAS | E2: 3L | F2: 2 | G2: 18000 | H2: =F2*G2 -> 36000 | I2: =+H2+H3 -> 96000 | J2: =SUM(I2:I655) -> 8839400
A3: 46243 | B3: DUEÑA DE CUBO | D3: CALATEA MACOYANA | E3: 3L | F3: 3 | G3: 20000 | H3: =F3*G3 -> 60000
A4: 46247 | B4: CLIENTE | D4: TIERRA NEGRA | E4: 25L | F4: 1 | G4: 8000 | H4: =F4*G4 -> 8000 | I4: =+H4 -> 8000
A5: 46248 | B5: JUJEÑO RENE | D5: LIRIO DEL AMAZONAS | E5: 3L | F5: 1 | G5: 8000 | H5: =F5*G5 -> 8000 | I5: =+H5+H7+H8+H6 -> 28800
A6: 46248 | B6: CLIENTE | D6: VIOLETA | E6: 0.5 | F6: 1 | G6: 2000 | H6: =F6*G6 -> 2000
A7: 46248 | B7: CLIENTE | D7: JAZMIN AMARILLO | E7: 4L | F7: 1 | G7: 8800 | H7: =F7*G7 -> 8800
A8: 46248 | B8: CLIENTE | D8: HELECHO ESPARRAGO | E8: 4L | F8: 1 | G8: 10000 | H8: =F8*G8 -> 10000
A9: 46249 | B9: CLIENTE | D9: BEGONIA DRAGON | E9: 1L | F9: 1 | G9: 6000 | H9: =F9*G9 -> 6000 | I9: =+H9+H10+H11 -> 11000
A10: 46249 | B10: CLIENTE | D10: CEDRON PARAGUAYO | E10: 0,5 L | F10: 1 | G10: 2500 | H10: =F10*G10 -> 2500
A11: 46249 | B11: CLIENTE | D11: OREGANO | E11: 0,5 L | F11: 1 | G11: 2500 | H11: =F11*G11 -> 2500
A12: 46250 | B12: Clarisa lopez | D12: CURRY | E12: 0.5 | F12: 1 | G12: 3000 | H12: =F12*G12 -> 3000 | I12: =+H12+H13+H14+H15+H16 -> 28000
A13: 46250 | B13: Clarisa lopez | D13: DRACENA WARNECKI | E13: 1L | F13: 1 | G13: 12000 | H13: =F13*G13 -> 12000
A14: 46250 | B14: Clarisa lopez | D14: maceta PLASTICO gris | E14: 3L | F14: 1 | G14: 3000 | H14: =F14*G14 -> 3000
A15: 46250 | B15: mirta | D15: TIERRA NEGRA | E15: 20L | F15: 1 | G15: 8000 | H15: =F15*G15 -> 8000
A16: 46250 | B16: mirta | D16: mantillo | E16: 10L | F16: 1 | G16: 2000 | H16: =F16*G16 -> 2000
A17: 46251 | B17: Gringa | D17: CROTO PETRA | E17: 3L | F17: 1 | G17: 14000 | H17: =F17*G17 -> 14000 | I17: =+H17+H18+H19 -> 80500
A18: 46251 | B18: MIRTA CABRAL MOTORS | D18: OLIVO | E18: 10L | F18: 1 | G18: 60000 | H18: =F18*G18 -> 60000
A19: 46251 | B19: CLIENTE RISIONE | D19: DIETE | E19: 5L | F19: 1 | G19: 6500 | H19: =F19*G19 -> 6500
A20: 46255 | B20: CHICO OJOS CLAROS | D20: CROTON | E20: 5L | F20: 2 | G20: 16000 | H20: =F20*G20 -> 32000 | I20: =SUM(H20:H21) -> 48000
A21: 46255 | B21: CHICO OJOS CLAROS | D21: COLOCACIA ESCULENTA | F21: 2 | G21: 8000 | H21: =F21*G21 -> 16000
A22: 46256 | B22: CLIENTE | D22: GOMERO VARIEGADO | E22: 3 | F22: 1 | G22: 14000 | H22: =F22*G22 -> 14000 | I22: =SUM(H22:H43) -> 316500
A23: 46256 | B23: CLIENTE | D23: GOMERO COMUN 1L | E23: 1 | F23: 1 | G23: 11000 | H23: =F23*G23 -> 11000
A24: 46256 | B24: CLIENTE | D24: GOTA Nº30 | F24: 1 | G24: 20000 | H24: =F24*G24 -> 20000
A25: 46256 | B25: CLIENTE | D25: PALMITO | E25: 5 | F25: 1 | G25: 22000 | H25: =F25*G25 -> 22000
A26: 46256 | B26: CENTU | D26: COLOCACIA ESCULENTA | F26: 1 | G26: 8000 | H26: =F26*G26 -> 8000
A27: 46256 | B27: CENTU | D27: GOMERO PINK | F27: 1 | G27: 19000 | H27: =F27*G27 -> 19000
A28: 46256 | B28: CLIENTA | D28: LAVANDA | F28: 2 | G28: 10000 | H28: =F28*G28 -> 20000
A29: 46256 | D29: CURRY | F29: 2 | G29: 3000 | H29: =F29*G29 -> 6000
A30: 46256 | D30: TOMILLO | F30: 1 | G30: 3000 | H30: =F30*G30 -> 3000
A31: 46256 | D31: SALVIA | F31: 2 | G31: 9000 | H31: =F31*G31 -> 18000
A32: 46256 | D32: BOLSA TIERRA AZUL | F32: 1 | G32: 8000 | H32: =F32*G32 -> 8000
A33: 46256 | D33: MANTILLO | F33: 1 | G33: 3000 | H33: =F33*G33 -> 3000
A34: 46256 | D34: CROTON | F34: 1 | G34: 18000 | H34: =F34*G34 -> 18000
A35: 46256 | D35: JAZMIN AMARILLO | F35: 1 | G35: 9000 | H35: =F35*G35 -> 9000
A36: 46256 | D36: GOMERO VARIEGADO | F36: 1 | G36: 25000 | H36: =F36*G36 -> 25000
A37: 46256 | B37: NORMA | D37: DRACENA WARNECKI | F37: 1 | G37: 9000 | H37: =F37*G37 -> 9000
A38: 46256 | B38: NORMA | D38: DRACENA LEMON | F38: 1 | G38: 9000 | H38: =F38*G38 -> 9000
A39: 46256 | B39: NORMA | D39: GOTA MINI | F39: 2 | G39: 6000 | H39: =F39*G39 -> 12000
A40: 46256 | B40: CARLA VILLALVA | D40: ANTHURIUM | F40: 1 | G40: 12000 | H40: =F40*G40 -> 12000
...

Sheet Costos
A1: COSTOS FIJOS | B1: 2026
A2: Concepto | B2: ABRIL | C2: MAYO | D2: JUNIO | E2: JULIO | F2: AGOSTO | G2: SEPTIEMBRE | H2: OCTUBRE | I2: NOVIEMBRE | J2: DICIEMBRE
A3: LUZ | B3: 42486.29 | C3: 42486.29 | D3: 42486.29 | E3: 42486.29 | F3: 42486.29 | G3: 42486.29 | H3: 42486.29 | I3: 42486.29 | J3: 42486.29
A4: AGUA | B4: 33498.05 | C4: 33498.05 | D4: 33498.05 | E4: 33498.05 | F4: 33498.05 | G4: 33498.05 | H4: 33498.05 | I4: 33498.05 | J4: 33498.05
A5: INTERNET | B5: 25000 | C5: 25000 | D5: 25000 | E5: 25000 | F5: 25000 | G5: 25000 | H5: 25000 | I5: 25000 | J5: 25000
A6: CAMARA | B6: 20000 | C6: 20000 | D6: 20000 | E6: 20000 | F6: 20000 | G6: 20000 | H6: 20000 | I6: 20000 | J6: 20000
A7: JORNALES
A9: COSTOS VARIABLES | B9: 2026
A10: concepto | B10: ABRIL | C10: MAYO | D10: JUNIO | E10: JULIO | F10: AGOSTO | G10: SEPTIEMBRE | H10: OCTUBRE | I10: NOVIEMBRE | J10: DICIEMBRE
A11: TIERRA NEGRA
A12: PLANTAS
A13: MACETAS
A14: SUSTRATOS
A15: FERTILIZANTES
A16: FITOSANITARIOS
A17: PIEDRAS
A18: COMBUSTIBLE

Sheet FlujoCaja
A1: Fecha | B1: Ingresos | C1: Egresos | D1: Saldo
A2: 46243 | B2: =SUM(Ventas!H2:H3) -> 96000 | D2: =B2-C2 -> 96000
A3: 46247 | B3: 8000 | D3: =B3-C3 -> 8000
A4: 46248 | B4: 28800 | D4: =B4-C4 -> 28800
A5: 46249 | B5: 11000 | D5: =B5-C5 -> 11000
A6: 46250 | B6: 28000 | D6: =B6-C6 -> 28000
A7: 46251 | B7: 80500 | D7: 80500
D10: =SUM(D2:D7) -> 252300
